Instance created. Preparing to start...
Starting download for registry01.prod.koyeb.com/k-4ec29468-4cb3-4292-aff5-8a48b8ac16ce/ce41366e-7269-4a82-8af0-d9cb1d149636:1ca5c3ac-51f6-4338-840a-8f5efdecf7ea
Download progress: 100% |[32m++++++++[0m| (13.8 MiB/s)
Download complete for registry01.prod.koyeb.com/k-4ec29468-4cb3-4292-aff5-8a48b8ac16ce/ce41366e-7269-4a82-8af0-d9cb1d149636:1ca5c3ac-51f6-4338-840a-8f5efdecf7ea
Instance is starting... Waiting for health checks to pass.
============================================
MIKU BOT FORCED STANDALONE MODE
This script bypasses Flask completely
============================================
2025-04-22 14:54:11,450 - run_miku_bot_standalone - INFO - BYPASS_CONFLICT_CHECK is set - skipping conflict detection
Exception in thread Thread-1 (start_health_server):
Traceback (most recent call last):
  File "/workspace/.heroku/python/lib/python3.11/threading.py", line 1045, in _bootstrap_inner
    self.run()
  File "/workspace/.heroku/python/lib/python3.11/threading.py", line 982, in run
    self._target(*self._args, **self._kwargs)
  File "/workspace/healthcheck.py", line 40, in start_health_server
    port = int(os.environ.get("PORT", 8000))
           ^^^^^^^^^^^^^^^^^^^^^^^^^^^^^^^^^
ValueError: invalid literal for int() with base 10: ''
2025-04-22 14:54:15,814 - api_clients - INFO - Reddit client initialized
2025-04-22 14:54:16,215 - reddit_tracker - INFO - Initialized tracking for r/5ToubunNoHanayome with post ID: 1k573y4
2025-04-22 14:54:16,382 - reddit_tracker - ERROR - Error initializing tracking for r/churchofmiku: received 404 HTTP response
2025-04-22 14:54:16,557 - reddit_tracker - INFO - Initialized tracking for r/MikuNakano with post ID: 1k583xl
2025-04-22 14:54:16,896 - reddit_tracker - INFO - Initialized tracking for r/5ToubunNoHanayome with post ID: 1k573y4
2025-04-22 14:54:17,049 - reddit_tracker - ERROR - Error initializing tracking for r/churchofmiku: received 404 HTTP response
2025-04-22 14:54:17,218 - reddit_tracker - INFO - Initialized tracking for r/MikuNakano with post ID: 1k583xl
2025-04-22 14:54:17,676 - apscheduler.scheduler - INFO - Adding job tentatively -- it will be properly scheduled when the scheduler starts
2025-04-22 14:54:17,677 - apscheduler.scheduler - INFO - Adding job tentatively -- it will be properly scheduled when the scheduler starts
2025-04-22 14:54:17,677 - apscheduler.scheduler - INFO - Adding job tentatively -- it will be properly scheduled when the scheduler starts
2025-04-22 14:54:17,677 - apscheduler.scheduler - INFO - Adding job tentatively -- it will be properly scheduled when the scheduler starts
2025-04-22 14:54:17,678 - scheduler - INFO - Scheduler set up successfully
2025-04-22 14:54:17,678 - bot - INFO - Starting bot...
2025-04-22 14:54:17,678 - apscheduler.scheduler - INFO - Added job "post_miku_fact" to job store "default"
2025-04-22 14:54:17,678 - apscheduler.scheduler - INFO - Added job "post_miku_image" to job store "default"
2025-04-22 14:54:17,679 - apscheduler.scheduler - INFO - Added job "post_reddit_miku" to job store "default"
2025-04-22 14:54:17,679 - apscheduler.scheduler - INFO - Added job "check_new_reddit_posts" to job store "default"
Bot setup successful. Starting to poll for updates...
Press Ctrl+C to stop the bot
2025-04-22 14:54:17,679 - apscheduler.scheduler - INFO - Scheduler started
2025-04-22 14:54:22,640 - apscheduler.executors.default - INFO - Running job "post_miku_fact (trigger: interval[0:10:00], next run at: 2025-04-22 14:54:22 UTC)" (scheduled at 2025-04-22 14:54:22.639638+00:00)
2025-04-22 14:54:44,311 - handlers - INFO - Downloading image from: https://safebooru.org/images/3698/6e083a87fcdfabbf...
2025-04-22 14:54:47,679 - apscheduler.executors.default - INFO - Running job "check_new_reddit_posts (trigger: interval[0:02:00], next run at: 2025-04-22 14:54:47 UTC)" (scheduled at 2025-04-22 14:54:47.677739+00:00)
2025-04-22 14:54:48,321 - apscheduler.executors.default - INFO - Job "check_new_reddit_posts (trigger: interval[0:02:00], next run at: 2025-04-22 14:56:47 UTC)" executed successfully
2025-04-22 14:54:58,787 - telegram.ext.updater - ERROR - Error while getting Updates: urllib3 HTTPError ('Connection aborted.', RemoteDisconnected('Remote end closed connection without response'))
2025-04-22 14:54:58,788 - telegram.ext.dispatcher - ERROR - No error handlers are registered, logging exception.
Traceback (most recent call last):
  File "/workspace/.heroku/python/lib/python3.11/site-packages/telegram/vendor/ptb_urllib3/urllib3/connectionpool.py", line 614, in urlopen
    httplib_response = self._make_request(conn, method, url,
                       ^^^^^^^^^^^^^^^^^^^^^^^^^^^^^^^^^^^^^
  File "/workspace/.heroku/python/lib/python3.11/site-packages/telegram/vendor/ptb_urllib3/urllib3/connectionpool.py", line 402, in _make_request
    six.raise_from(e, None)
  File "<string>", line 2, in raise_from
  File "/workspace/.heroku/python/lib/python3.11/site-packages/telegram/vendor/ptb_urllib3/urllib3/connectionpool.py", line 398, in _make_request
    httplib_response = conn.getresponse()
                       ^^^^^^^^^^^^^^^^^^
  File "/workspace/.heroku/python/lib/python3.11/http/client.py", line 1395, in getresponse
    response.begin()
  File "/workspace/.heroku/python/lib/python3.11/http/client.py", line 325, in begin
    version, status, reason = self._read_status()
                              ^^^^^^^^^^^^^^^^^^^
  File "/workspace/.heroku/python/lib/python3.11/http/client.py", line 294, in _read_status
    raise RemoteDisconnected("Remote end closed connection without"
http.client.RemoteDisconnected: Remote end closed connection without response

During handling of the above exception, another exception occurred:

Traceback (most recent call last):
  File "/workspace/.heroku/python/lib/python3.11/site-packages/telegram/utils/request.py", line 259, in _request_wrapper
    resp = self._con_pool.request(*args, **kwargs)
           ^^^^^^^^^^^^^^^^^^^^^^^^^^^^^^^^^^^^^^^
  File "/workspace/.heroku/python/lib/python3.11/site-packages/telegram/vendor/ptb_urllib3/urllib3/request.py", line 68, in request
    return self.request_encode_body(method, url, fields=fields,
           ^^^^^^^^^^^^^^^^^^^^^^^^^^^^^^^^^^^^^^^^^^^^^^^^^^^^
  File "/workspace/.heroku/python/lib/python3.11/site-packages/telegram/vendor/ptb_urllib3/urllib3/request.py", line 148, in request_encode_body
    return self.urlopen(method, url, **extra_kw)
           ^^^^^^^^^^^^^^^^^^^^^^^^^^^^^^^^^^^^^
  File "/workspace/.heroku/python/lib/python3.11/site-packages/telegram/vendor/ptb_urllib3/urllib3/poolmanager.py", line 244, in urlopen
    response = conn.urlopen(method, u.request_uri, **kw)
               ^^^^^^^^^^^^^^^^^^^^^^^^^^^^^^^^^^^^^^^^^
  File "/workspace/.heroku/python/lib/python3.11/site-packages/telegram/vendor/ptb_urllib3/urllib3/connectionpool.py", line 665, in urlopen
    retries = retries.increment(method, url, error=e, _pool=self,
              ^^^^^^^^^^^^^^^^^^^^^^^^^^^^^^^^^^^^^^^^^^^^^^^^^^^
  File "/workspace/.heroku/python/lib/python3.11/site-packages/telegram/vendor/ptb_urllib3/urllib3/util/retry.py", line 347, in increment
    raise six.reraise(type(error), error, _stacktrace)
          ^^^^^^^^^^^^^^^^^^^^^^^^^^^^^^^^^^^^^^^^^^^^
  File "/workspace/.heroku/python/lib/python3.11/site-packages/telegram/vendor/ptb_urllib3/urllib3/packages/six.py", line 685, in reraise
    raise value.with_traceback(tb)
  File "/workspace/.heroku/python/lib/python3.11/site-packages/telegram/vendor/ptb_urllib3/urllib3/connectionpool.py", line 614, in urlopen
    httplib_response = self._make_request(conn, method, url,
                       ^^^^^^^^^^^^^^^^^^^^^^^^^^^^^^^^^^^^^
  File "/workspace/.heroku/python/lib/python3.11/site-packages/telegram/vendor/ptb_urllib3/urllib3/connectionpool.py", line 402, in _make_request
    six.raise_from(e, None)
  File "<string>", line 2, in raise_from
  File "/workspace/.heroku/python/lib/python3.11/site-packages/telegram/vendor/ptb_urllib3/urllib3/connectionpool.py", line 398, in _make_request
    httplib_response = conn.getresponse()
                       ^^^^^^^^^^^^^^^^^^
  File "/workspace/.heroku/python/lib/python3.11/http/client.py", line 1395, in getresponse
    response.begin()
  File "/workspace/.heroku/python/lib/python3.11/http/client.py", line 325, in begin
    version, status, reason = self._read_status()
                              ^^^^^^^^^^^^^^^^^^^
  File "/workspace/.heroku/python/lib/python3.11/http/client.py", line 294, in _read_status
    raise RemoteDisconnected("Remote end closed connection without"
telegram.vendor.ptb_urllib3.urllib3.exceptions.ProtocolError: ('Connection aborted.', RemoteDisconnected('Remote end closed connection without response'))

The above exception was the direct cause of the following exception:

Traceback (most recent call last):
  File "/workspace/.heroku/python/lib/python3.11/site-packages/telegram/ext/updater.py", line 651, in _network_loop_retry
    if not action_cb():
           ^^^^^^^^^^^
  File "/workspace/.heroku/python/lib/python3.11/site-packages/telegram/ext/updater.py", line 602, in polling_action_cb
    updates = self.bot.get_updates(
              ^^^^^^^^^^^^^^^^^^^^^
  File "/workspace/.heroku/python/lib/python3.11/site-packages/telegram/ext/extbot.py", line 228, in get_updates
    updates = super().get_updates(
              ^^^^^^^^^^^^^^^^^^^^
  File "/workspace/.heroku/python/lib/python3.11/site-packages/telegram/bot.py", line 134, in decorator
    result = func(*args, **kwargs)
             ^^^^^^^^^^^^^^^^^^^^^
  File "/workspace/.heroku/python/lib/python3.11/site-packages/telegram/bot.py", line 3140, in get_updates
    self._post(
  File "/workspace/.heroku/python/lib/python3.11/site-packages/telegram/bot.py", line 299, in _post
    return self.request.post(
           ^^^^^^^^^^^^^^^^^^
  File "/workspace/.heroku/python/lib/python3.11/site-packages/telegram/utils/request.py", line 361, in post
    result = self._request_wrapper(
             ^^^^^^^^^^^^^^^^^^^^^^
  File "/workspace/.heroku/python/lib/python3.11/site-packages/telegram/utils/request.py", line 265, in _request_wrapper
    raise NetworkError(f'urllib3 HTTPError {error}') from error
telegram.error.NetworkError: urllib3 HTTPError ('Connection aborted.', RemoteDisconnected('Remote end closed connection without response'))
2025-04-22 14:55:08,899 - handlers - ERROR - Error downloading image: HTTPSConnectionPool(host='safebooru.org', port=443): Read timed out.
2025-04-22 14:55:08,899 - handlers - INFO - Falling back to direct URL...